Workbook

Sheet power_meta
A1: baseMVA
A2: 100

Sheet power_bus
A1: BUS_I | B1: BUS_TYPE | C1: PD | D1: QD | E1: GS | F1: BS | G1: BUS_AREA | H1: VM | I1: VA | J1: BASE_KV | K1: ZONE | L1: VMAX | M1: VMIN
A2: 1 | B2: 2 | C2: 2 | D2: 0 | E2: 0 | F2: 0 | G2: 1 | H2: 1 | I2: 0 | J2: 110 | K2: 1 | L2: 1.1 | M2: 0.9
A3: 2 | B3: 3 | C3: 3 | D3: 0 | E3: 0 | F3: 0 | G3: 1 | H3: 1 | I3: 0 | J3: 110 | K3: 1 | L3: 1.1 | M3: 0.9
A4: 3 | B4: 1 | C4: 2.8 | D4: 0 | E4: 0 | F4: 0 | G4: 1 | H4: 1 | I4: 0 | J4: 110 | K4: 1 | L4: 1.1 | M4: 0.9
A5: 4 | B5: 2 | C5: 1 | D5: 0.5 | E5: 0 | F5: 0 | G5: 1 | H5: 1 | I5: 0 | J5: 110 | K5: 1 | L5: 1.1 | M5: 0.9
A6: 5 | B6: 1 | C6: 2.8 | D6: 1.2 | E6: 0 | F6: 0 | G6: 1 | H6: 1 | I6: 0 | J6: 110 | K6: 1 | L6: 1.1 | M6: 0.9
A7: 6 | B7: 1 | C7: 2 | D7: 1.2 | E7: 0 | F7: 0 | G7: 1 | H7: 1 | I7: 0 | J7: 110 | K7: 1 | L7: 1.1 | M7: 0.9
A8: 7 | B8: 2 | C8: 0 | D8: 0 | E8: 0 | F8: 0 | G8: 1 | H8: 1 | I8: 0 | J8: 110 | K8: 1 | L8: 1.1 | M8: 0.9

Sheet power_gen
A1: 0 | B1: 1 | C1: 2 | D1: 3 | E1: 4 | F1: 5 | G1: 6 | H1: 7 | I1: 8 | J1: 9
A2: 1 | B2: 5 | C2: 0 | D2: 300 | E2: -300 | F2: 1 | G2: 1 | H2: 100 | I2: 5 | J2: 0
A3: 2 | B3: 5 | C3: 0 | D3: 300 | E3: -300 | F3: 1 | G3: 1 | H3: 100 | I3: 5 | J3: 0
A4: 7 | B4: 0 | C4: 0 | D4: 300 | E4: -300 | F4: 1 | G4: 1 | H4: 100 | I4: 10 | J4: 0

Sheet power_branch
A1: F_BUS | B1: T_BUS | C1: BR_R | D1: BR_X | E1: BR_B | F1: RATE_A | G1: RATE_B | H1: RATE_C | I1: TAP | J1: SHIFT | K1: BR_STATUS | L1: ANGMIN | M1: ANGMAX
A2: 1 | B2: 2 | C2: 0.1 | D2: 0.2 | E2: 0.04 | F2: 200 | G2: 200 | H2: 200 | I2: 0 | J2: 0 | K2: 1 | L2: -360 | M2: 360
A3: 1 | B3: 6 | C3: 0.25 | D3: 0.5 | E3: 0.04 | F3: 200 | G3: 200 | H3: 200 | I3: 0 | J3: 0 | K3: 1 | L3: -360 | M3: 360
A4: 2 | B4: 3 | C4: 0.15 | D4: 0.3 | E4: 0.06 | F4: 200 | G4: 200 | H4: 200 | I4: 0 | J4: 0 | K4: 1 | L4: -360 | M4: 360
A5: 2 | B5: 6 | C5: 0.25 | D5: 0.5 | E5: 0.02 | F5: 200 | G5: 200 | H5: 200 | I5: 0 | J5: 0 | K5: 1 | L5: -360 | M5: 360
A6: 3 | B6: 4 | C6: 0.12 | D6: 0.26 | E6: 0.05 | F6: 200 | G6: 200 | H6: 200 | I6: 0 | J6: 0 | K6: 1 | L6: -360 | M6: 360
A7: 4 | B7: 5 | C7: 0.2 | D7: 0.4 | E7: 0.08 | F7: 300 | G7: 300 | H7: 300 | I7: 0 | J7: 0 | K7: 1 | L7: -360 | M7: 360
A8: 5 | B8: 6 | C8: 0.2 | D8: 0.4 | E8: 0.06 | F8: 200 | G8: 200 | H8: 200 | I8: 0 | J8: 0 | K8: 1 | L8: -360 | M8: 360
A9: 7 | B9: 1 | C9: 0.1 | D9: 0.2 | E9: 0.04 | F9: 200 | G9: 200 | H9: 200 | I9: 0 | J9: 0 | K9: 1 | L9: -360 | M9: 360

Sheet storage_system
A1: id | B1: bus | C1: Pch_max | D1: Pdc_max | E1: eta_ch | F1: eta_dc | G1: kappa | H1: e_min | I1: e_max | J1: e0 | K1: w_es0 | L1: model
A2: ES1 | B2: 3 | C2: 5 | D2: 5 | E2: 0.95 | F2: 0.95 | G2: 0.999 | H2: 0.5 | I2: 30 | J2: 10 | K2: 0.3 | L2: water_tank

Sheet power_gci
A1: GCI
A2: 0.3
A3: 0
A4: 0.4

Sheet gas_nodes
A1: id | B1: pressure | C1: max_pressure | D1: min_pressure | E1: injection | F1: CEFR
A2: 1 | B2: 140 | C2: 150 | D2: 100 | E2: 0 | F2: 0
A3: 2 | C3: 150 | D3: 100 | E3: 0 | F3: 0
A4: 3 | C4: 150 | D4: 100 | E4: 0 | F4: 0
A5: 4 | C5: 150 | D5: 100 | E5: 0 | F5: 0
A6: 5 | C6: 150 | D6: 100 | E6: 0 | F6: 0
A7: 6 | C7: 150 | D7: 100 | E7: 0 | F7: 0

Sheet gas_pipelines
A1: id | B1: from | C1: to | D1: flowrate | E1: Kp | F1: Capacity | G1: CEFR
A2: 1 | B2: 1 | C2: 2 | D2: 0 | E2: 3.426 | F2: 300 | G2: 0
A3: 2 | B3: 2 | C3: 3 | D3: 0 | E3: 3.096 | F3: 300 | G3: 0
A4: 3 | B4: 2 | C4: 5 | D4: 0 | E4: 1.707 | F4: 150 | G4: 0
A5: 4 | B5: 4 | C5: 5 | D5: 0 | E5: 3.053 | F5: 300 | G5: 0
A6: 5 | B6: 5 | C6: 6 | D6: 0 | E6: 2.565 | F6: 200 | G6: 0

Sheet gas_compressors
A1: id | B1: location | C1: type | D1: powerconsumption | E1: gasconsumption
A2: 1 | B2: 2 | C2: turbo | E2: 4.91
A3: 2 | B3: 4 | C3: electric | E3: 0

Sheet gas_sources
A1: id | B1: node | C1: output | D1: GCI | E1: is_slack
A2: 1 | B2: 1 | C2: =0.0122*267.29 -> 3.260938 | D2: 0.2 | E2: 1
A3: 2 | B3: 4 | C3: =0.012*205 -> 2.46 | D3: 0.2 | E3: 0

Sheet gas_loads
A1: id | B1: node | C1: demand
A2: 1 | B2: 2 | C2: =0.012*150 -> 1.8
A3: 2 | B3: 3 | C3: =0.012*150 -> 1.8
A4: 3 | B4: 5 | C4: =0.012*99.04 -> 1.18848
A5: 4 | B5: 6 | C5: =0.012*68.34 -> 0.82008

Sheet heat_nodes
A1: id | B1: type | C1: pressure | D1: injection | E1: temperature
A2: 1 | B2: 定压力 | C2: 3 | D2: 0 | E2: 100
A3: 2 | B3: 定注入 | C3: 0 | D3: 0 | E3: 0
A4: 3 | B4: 定注入 | C4: 0 | D4: 0 | E4: 0
A5: 4 | B5: 定注入 | C5: 0 | D5: 0 | E5: 0
A6: 5 | B6: 定注入 | C6: 0 | D6: 0 | E6: 0
A7: 6 | B7: 定注入 | C7: 0 | D7: 0 | E7: 0
A8: 7 | B8: 定注入 | C8: 0 | D8: -300 | E8: 0
A9: 8 | B9: 定注入 | C9: 0 | D9: 0 | E9: 0
A10: 9 | B10: 定注入 | C10: 0 | D10: 0 | E10: 0
A11: 10 | B11: 定注入 | C11: 0 | D11: 0 | E11: 0
A12: 11 | B12: 定注入 | C12: 0 | D12: 0 | E12: 0
A13: 12 | B13: 定注入 | C13: 0 | D13: 0 | E13: 0

Sheet heat_pipelines
A1: id | B1: from | C1: to | D1: length | E1: diameter | F1: friction_factor | G1: deltaT | H1: dissipation | I1: valve | J1: pump | K1: massflow | L1: T_in | M1: T_out | N1: heat_loss
A2: 1 | B2: 1 | C2: 2 | D2: 3000 | E2: 0.4 | F2: 0.05 | G2: 0 | H2: 1.5 | I2: 0 | J2: 0 | K2: 0 | L2: 0 | M2: 0 | N2: 0
A3: 2 | B3: 2 | C3: 3 | D3: 5000 | E3: 0.4 | F3: 0.05 | G3: 0 | H3: 1.5 | I3: 0 | J3: 0 | K3: 0 | L3: 0 | M3: 0 | N3: 0
A4: 3 | B4: 3 | C4: 5 | D4: 3000 | E4: 0.25 | F4: 0.05 | G4: 0 | H4: 1.5 | I4: 0 | J4: 1 | K4: 0 | L4: 0 | M4: 0 | N4: 0
A5: 4 | B5: 2 | C5: 6 | D5: 4000 | E5: 0.25 | F5: 0.05 | G5: 0 | H5: 1.5 | I5: 1 | J5: 0 | K5: 0 | L5: 0 | M5: 0 | N5: 0
A6: 5 | B6: 3 | C6: 4 | D6: 4000 | E6: 0.25 | F6: 0.05 | G6: 0 | H6: 1.5 | I6: 0 | J6: 2 | K6: 0 | L6: 0 | M6: 0 | N6: 0
A7: 6 | B7: 8 | C7: 7 | D7: 3000 | E7: 0.4 | F7: 0.05 | G7: 0 | H7: 1.5 | I7: 0 | J7: 0 | K7: 0 | L7: 0 | M7: 0 | N7: 0
A8: 7 | B8: 9 | C8: 8 | D8: 5000 | E8: 0.4 | F8: 0.05 | G8: 0 | H8: 1.5 | I8: 0 | J8: 0 | K8: 0 | L8: 0 | M8: 0 | N8: 0
A9: 8 | B9: 11 | C9: 9 | D9: 3000 | E9: 0.25 | F9: 0.05 | G9: 0 | H9: 1.5 | I9: 0 | J9: 0 | K9: 0 | L9: 0 | M9: 0 | N9: 0
A10: 9 | B10: 12 | C10: 8 | D10: 4000 | E10: 0.25 | F10: 0.05 | G10: 0 | H10: 1.5 | I10: 0 | J10: 0 | K10: 0 | L10: 0 | M10: 0 | N10: 0
A11: 10 | B11: 10 | C11: 9 | D11: 4000 | E11: 0.25 | F11: 0.05 | G11: 0 | H11: 1.5 | I11: 0 | J11: 0 | K11: 0 | L11: 0 | M11: 0 | N11: 0
A12: 11 | B12: 6 | C12: 12 | D12: 200 | E12: 0.2 | F12: 0.08 | G12: -20 | H12: 0 | I12: 0 | J12: 0 | K12: 0 | L12: 0 | M12: 0 | N12: 0
A13: 12 | B13: 4 | C13: 10 | D13: 200 | E13: 0.2 | F13: 0.08 | G13: -25 | H13: 0 | I13: 0 | J13: 0 | K13: 0 | L13: 0 | M13: 0 | N13: 0
A14: 13 | B14: 5 | C14: 11 | D14: 200 | E14: 0.2 | F14: 0.08 | G14: -20 | H14: 0 | I14: 0 | J14: 0 | K14: 0 | L14: 0 | M14: 0 | N14: 0

Sheet heat_valves
A1: id | B1: kv
A2: 1 | B2: 6.13

Sheet heat_pumps
A1: id | B1: kp1 | C1: kp2 | D1: kp3 | E1: w
A2: 1 | B2: -4.75 | C2: -2.77 | D2: 72.81 | E2: 75
A3: 2 | B3: -4.75 | C3: -2.77 | D3: 72.81 | E3: 75

Sheet heat_sources
A1: id | B1: node | C1: output | D1: GCI
A2: 1 | B2: 1

Sheet heat_loads
A1: id | B1: node | C1: demand
A2: 1 | B2: 6 | C2: -20
A3: 2 | B3: 4 | C3: -25
A4: 3 | B4: 5 | C4: -20

Sheet eh_meta
A1: powernode | B1: gasnode | C1: mode
A2: 5 | B2: 5 | C2: heat_priority

Sheet eh_inputs
A1: type | B1: flow | C1: PCI
A2: electricity
A3: gas

Sheet eh_outputs
A1: type | B1: flow | C1: PCI | D1: CEFR
A2: electricity_o1
A3: electricity_o2
A4: heat_o1
A5: heat_o2
A6: cooling_o1
A7: cooling_o2

Sheet _schema
A1: sheet | B1: field | C1: unit | D1: required_sheet | E1: dtype | F1: rules | G1: notes
A2: power_meta | B2: baseMVA | D2: Y | E2: int64
A3: power_bus | B3: BUS_I | D3: Y | E3: int64
A4: power_bus | B4: BUS_TYPE | D4: Y | E4: int64
A5: power_bus | B5: PD | C5: MW | D5: Y | E5: int64
A6: power_bus | B6: QD | C6: MVAr | D6: Y | E6: int64
A7: power_bus | B7: GS | D7: Y | E7: int64
A8: power_bus | B8: BS | D8: Y | E8: int64
A9: power_bus | B9: BUS_AREA | D9: Y | E9: int64
A10: power_bus | B10: VM | C10: p.u. | D10: Y | E10: int64
A11: power_bus | B11: VA | C11: deg | D11: Y | E11: int64
A12: power_bus | B12: BASE_KV | C12: kV | D12: Y | E12: int64
A13: power_bus | B13: ZONE | D13: Y | E13: int64
A14: power_bus | B14: VMAX | D14: Y | E14: float64
A15: power_bus | B15: VMIN | D15: Y | E15: float64
A16: power_gen | B16: 0 | D16: Y | E16: int64
A17: power_gen | B17: 1 | D17: Y | E17: int64
A18: power_gen | B18: 2 | D18: Y | E18: int64
A19: power_gen | B19: 3 | D19: Y | E19: int64
A20: power_gen | B20: 4 | D20: Y | E20: int64
A21: power_gen | B21: 5 | D21: Y | E21: int64
A22: power_gen | B22: 6 | D22: Y | E22: int64
A23: power_gen | B23: 7 | D23: Y | E23: int64
A24: power_gen | B24: 8 | D24: Y | E24: int64
... A27: power_branch | B27: T_BUS | D27: Y | E27: int64
A28: power_branch | B28: BR_R | C28: p.u. | D28: Y | E28: float64
A29: power_branch | B29: BR_X | C29: p.u. | D29: Y | E29: float64
A30: power_branch | B30: BR_B | C30: p.u. | D30: Y | E30: float64
A31: power_branch | B31: RATE_A | C31: MVA | D31: Y | E31: int64
A32: power_branch | B32: RATE_B | C32: MVA | D32: Y | E32: int64
A33: power_branch | B33: RATE_C | C33: MVA | D33: Y | E33: int64
A34: power_branch | B34: TAP | D34: Y | E34: int64
A35: power_branch | B35: SHIFT | D35: Y | E35: int64
A36: power_branch | B36: BR_STATUS | D36: Y | E36: int64
A37: power_branch | B37: ANGMIN | D37: Y | E37: int64
A38: power_branch | B38: ANGMAX | D38: Y | E38: int64
A39: power_gci | B39: GCI | D39: Y | E39: float64
A40: gas_nodes | B40: id | D40: Y | E40: int64
A41: gas_nodes | B41: pressure | C41: MPa | D41: Y | E41: float64
A42: gas_nodes | B42: max_pressure | D42: Y | E42: int64
...

Sheet power_PD
A1: BUS_I | B1: H00 | C1: H01 | D1: H02 | E1: H03 | F1: H04 | G1: H05 | H1: H06 | I1: H07 | J1: H08 | K1: H09 | L1: H10 | M1: H11 | N1: H12 | O1: H13 | P1: H14 | Q1: H15 | R1: H16 | S1: H17 | T1: H18 | U1: H19 | V1: H20 | W1: H21 | X1: H22 | Y1: H23
A2: 1 | B2: 2.63961 | C2: 2.44542 | D2: 2.61416 | E2: 2.53827 | F2: 2.07563 | G2: 2.01496 | H2: 2.01278 | I2: 1.81554 | J2: 1.69857 | K2: 1.50853 | L2: 1.54548 | M2: 1.47569 | N2: 1.40462 | O2: 1.5005 | P2: 1.51499 | Q2: 1.50804 | R2: 1.73134 | S2: 1.75627 | T2: 2.08785 | U2: 2.14991 | V2: 2.27874 | W2: 2.34173 | X2: 2.67363 | Y2: 2.55962
A3: 2 | B3: 4.03239 | C3: 3.88241 | D3: 3.83406 | E3: 3.75118 | F3: 3.19864 | G3: 3.18126 | H3: 2.92944 | I3: 2.67867 | J3: 2.51492 | K3: 2.54028 | L3: 2.12444 | M3: 2.23382 | N3: 1.9233 | O3: 2.09499 | P3: 2.23865 | Q3: 2.43288 | R3: 2.64068 | S3: 2.87682 | T3: 2.94769 | U3: 3.1582 | V3: 3.598 | W3: 3.60161 | X3: 3.53835 | Y3: 3.65008
A4: 3 | B4: 3.39927 | C4: 3.43131 | D4: 3.59797 | E4: 3.24031 | F4: 3.15912 | G4: 3.21342 | H4: 2.75012 | I4: 2.67783 | J4: 2.2689 | K4: 2.18337 | L4: 1.97409 | M4: 1.95491 | N4: 2.04235 | O4: 1.81687 | P4: 2.11756 | Q4: 2.23225 | R4: 2.3093 | S4: 2.39586 | T4: 2.8101 | U4: 2.93752 | V4: 3.25746 | W4: 3.39768 | X4: 3.80997 | Y4: 3.56816
A5: 4 | B5: 1.24716 | C5: 1.26299 | D5: 1.22125 | E5: 1.2036 | F5: 1.21129 | G5: 1.08611 | H5: 0.99207 | I5: 0.87459 | J5: 0.77883 | K5: 0.76871 | L5: 0.7382 | M5: 0.773 | N5: 0.70456 | O5: 0.74512 | P5: 0.72171 | Q5: 0.74119 | R5: 0.80898 | S5: 0.88891 | T5: 1.10642 | U5: 1.03339 | V5: 1.19821 | W5: 1.15741 | X5: 1.31849 | Y5: 1.3146
A6: 5 | B6: 3.57026 | C6: 3.87527 | D6: 3.33221 | E6: 3.24214 | F6: 3.32358 | G6: 2.95787 | H6: 2.79928 | I6: 2.56149 | J6: 2.42017 | K6: 2.36128 | L6: 2.08193 | M6: 2.05265 | N6: 1.75908 | O6: 1.98378 | P6: 1.98516 | Q6: 2.07159 | R6: 2.2755 | S6: 2.53945 | T6: 2.92823 | U6: 2.81729 | V6: 3.22493 | W6: 3.31181 | X6: 3.46967 | Y6: 3.79244
A7: 6 | B7: 2.48601 | C7: 2.5674 | D7: 2.29818 | E7: 2.24644 | F7: 2.54486 | G7: 2.01655 | H7: 1.89032 | I7: 2.01414 | J7: 1.94693 | K7: 1.48343 | L7: 1.45313 | M7: 1.4447 | N7: 1.52101 | O7: 1.35036 | P7: 1.46223 | Q7: 1.63698 | R7: 1.73696 | S7: 1.81001 | T7: 1.98662 | U7: 2.00713 | V7: 2.27261 | W7: 2.39197 | X7: 2.54886 | Y7: 2.50793

Sheet power_QD
A1: BUS_I | B1: H00 | C1: H01 | D1: H02 | E1: H03 | F1: H04 | G1: H05 | H1: H06 | I1: H07 | J1: H08 | K1: H09 | L1: H10 | M1: H11 | N1: H12 | O1: H13 | P1: H14 | Q1: H15 | R1: H16 | S1: H17 | T1: H18 | U1: H19 | V1: H20 | W1: H21 | X1: H22 | Y1: H23
A2: 1 | B2: 0.001 | C2: 0.001 | D2: 0.001 | E2: 0.001 | F2: 0.001 | G2: 0.001 | H2: 0.001 | I2: 0.001 | J2: 0.001 | K2: 0.001 | L2: 0.001 | M2: 0.001 | N2: 0.001 | O2: 0.001 | P2: 0.001 | Q2: 0.001 | R2: 0.001 | S2: 0.001 | T2: 0.001 | U2: 0.001 | V2: 0.001 | W2: 0.001 | X2: 0.001 | Y2: 0.001
A3: 2 | B3: 0.001 | C3: 0.001 | D3: 0.001 | E3: 0.001 | F3: 0.001 | G3: 0.001 | H3: 0.001 | I3: 0.001 | J3: 0.001 | K3: 0.001 | L3: 0.001 | M3: 0.001 | N3: 0.001 | O3: 0.001 | P3: 0.001 | Q3: 0.001 | R3: 0.001 | S3: 0.001 | T3: 0.001 | U3: 0.001 | V3: 0.001 | W3: 0.001 | X3: 0.001 | Y3: 0.001
A4: 3 | B4: 0.001 | C4: 0.001 | D4: 0.001 | E4: 0.001 | F4: 0.001 | G4: 0.001 | H4: 0.001 | I4: 0.001 | J4: 0.001 | K4: 0.001 | L4: 0.001 | M4: 0.001 | N4: 0.001 | O4: 0.001 | P4: 0.001 | Q4: 0.001 | R4: 0.001 | S4: 0.001 | T4: 0.001 | U4: 0.001 | V4: 0.001 | W4: 0.001 | X4: 0.001 | Y4: 0.001
A5: 4 | B5: 0.62011 | C5: 0.61948 | D5: 0.58834 | E5: 0.60151 | F5: 0.5497 | G5: 0.49973 | H5: 0.46805 | I5: 0.47168 | J5: 0.47204 | K5: 0.4149 | L5: 0.38942 | M5: 0.38468 | N5: 0.39949 | O5: 0.38342 | P5: 0.3837 | Q5: 0.43438 | R5: 0.44688 | S5: 0.50356 | T5: 0.50458 | U5: 0.49976 | V5: 0.52402 | W5: 0.63696 | X5: 0.66067 | Y5: 0.61517
A6: 5 | B6: 1.54036 | C6: 1.5894 | D6: 1.44853 | E6: 1.36299 | F6: 1.33489 | G6: 1.29314 | H6: 1.21059 | I6: 1.0615 | J6: 1.05475 | K6: 0.99914 | L6: 1.05854 | M6: 0.99564 | N6: 0.8616 | O6: 0.89714 | P6: 0.8714 | Q6: 0.95869 | R6: 1.06657 | S6: 1.19002 | T6: 1.15625 | U6: 1.23586 | V6: 1.20506 | W6: 1.40065 | X6: 1.38226 | Y6: 1.45034
A7: 6 | B7: 1.53537 | C7: 1.56521 | D7: 1.47115 | E7: 1.43697 | F7: 1.35359 | G7: 1.27765 | H7: 1.15671 | I7: 1.14012 | J7: 1.04489 | K7: 1.09126 | L7: 1.01416 | M7: 0.92778 | N7: 0.86566 | O7: 0.8596 | P7: 0.99619 | Q7: 1.00085 | R7: 1.07521 | S7: 1.02445 | T7: 1.25565 | U7: 1.30668 | V7: 1.27505 | W7: 1.37884 | X7: 1.47906 | Y7: 1.49369

Sheet gen_PG
A1: gen_id | B1: H00 | C1: H01 | D1: H02 | E1: H03 | F1: H04 | G1: H05 | H1: H06 | I1: H07 | J1: H08 | K1: H09 | L1: H10 | M1: H11 | N1: H12 | O1: H13 | P1: H14 | Q1: H15 | R1: H16 | S1: H17 | T1: H18 | U1: H19 | V1: H20 | W1: H21 | X1: H22 | Y1: H23
A2: 1 | B2: 0.11825 | C2: 0.1187 | D2: 0.11584 | E2: 0.11501 | F2: 0.11809 | G2: 0.09168 | H2: 0.09882 | I2: 0.09566 | J2: 0.09133 | K2: 0.08426 | L2: 0.07542 | M2: 0.082 | N2: 0.08691 | O2: 0.07449 | P2: 0.08625 | Q2: 0.08445 | R2: 0.08972 | S2: 0.08983 | T2: 0.09833 | U2: 0.11201 | V2: 0.1132 | W2: 0.12403 | X2: 0.12423 | Y2: 0.12194
A3: 2 | B3: 0.13046 | C3: 0.12194 | D3: 0.12218 | E3: 0.11245 | F3: 0.11037 | G3: 0.10151 | H3: 0.10495 | I3: 0.08924 | J3: 0.09352 | K3: 0.08504 | L3: 0.08752 | M3: 0.08371 | N3: 0.08728 | O3: 0.08363 | P3: 0.07618 | Q3: 0.08557 | R3: 0.08473 | S3: 0.09237 | T3: 0.10756 | U3: 0.10853 | V3: 0.10616 | W3: 0.10836 | X3: 0.11751 | Y3: 0.11206

Sheet gen_PMAX
A1: gen_id | B1: PMAX_ref
A2: 1 | B2: 20
A3: 2 | B3: 20
A4: 3 | B4: 20

Sheet eh_flow_electricity
A1: type | B1: H00 | C1: H01 | D1: H02 | E1: H03 | F1: H04 | G1: H05 | H1: H06 | I1: H07 | J1: H08 | K1: H09 | L1: H10 | M1: H11 | N1: H12 | O1: H13 | P1: H14 | Q1: H15 | R1: H16 | S1: H17 | T1: H18 | U1: H19 | V1: H20 | W1: H21 | X1: H22 | Y1: H23
A2: electricity | B2: =power_PD!B6 -> 3.57026 | C2: =power_PD!C6 -> 3.87527 | D2: =power_PD!D6 -> 3.33221 | E2: =power_PD!E6 -> 3.24214 | F2: =power_PD!F6 -> 3.32358 | G2: =power_PD!G6 -> 2.95787 | H2: =power_PD!H6 -> 2.79928 | I2: =power_PD!I6 -> 2.56149 | ... Y2: =power_PD!Y6 -> 3.79244

Sheet eh_flow_gas
A1: type | B1: H00 | C1: H01 | D1: H02 | E1: H03 | F1: H04 | G1: H05 | H1: H06 | I1: H07 | J1: H08 | K1: H09 | L1: H10 | M1: H11 | N1: H12 | O1: H13 | P1: H14 | Q1: H15 | R1: H16 | S1: H17 | T1: H18 | U1: H19 | V1: H20 | W1: H21 | X1: H22 | Y1: H23
A2: gas | B2: 21.94 | C2: 20.278 | D2: 23.951 | E2: 21.665 | F2: 21.303 | G2: 19.669 | H2: 17.529 | I2: 16.304 | J2: 15.164 | K2: 19.148 | L2: 17.788 | M2: 18.27 | N2: 17.129 | O2: 16.342 | P2: 18 | Q2: 13.276 | R2: 15.214 | S2: 16.86 | T2: 18.939 | U2: 20.831 | V2: 17.478 | W2: 18.719 | X2: 18.671 | Y2: 21.377

Sheet gas_load_demand
A1: load_id | B1: node | C1: H00 | D1: H01 | E1: H02 | F1: H03 | G1: H04 | H1: H05 | I1: H06 | J1: H07 | K1: H08 | L1: H09 | M1: H10 | N1: H11 | O1: H12 | P1: H13 | Q1: H14 | R1: H15 | S1: H16 | T1: H17 | U1: H18 | V1: H19 | W1: H20 | X1: H21 | Y1: H22 | Z1: H23
A2: 1 | B2: 2 | C2: 1.8 | D2: 1.8 | E2: 1.8 | F2: 1.8 | G2: 1.8 | H2: 1.8 | I2: 1.8 | J2: 1.8 | K2: 1.8 | L2: 1.8 | M2: 1.8 | N2: 1.8 | O2: 1.8 | P2: 1.8 | Q2: 1.8 | R2: 1.8 | S2: 1.8 | T2: 1.8 | U2: 1.8 | V2: 1.8 | W2: 1.8 | X2: 1.8 | Y2: 1.8 | Z2: 1.8
A3: 2 | B3: 3 | C3: 1.8 | D3: 1.8 | E3: 1.8 | F3: 1.8 | G3: 1.8 | H3: 1.8 | I3: 1.8 | J3: 1.8 | K3: 1.8 | L3: 1.8 | M3: 1.8 | N3: 1.8 | O3: 1.8 | P3: 1.8 | Q3: 1.8 | R3: 1.8 | S3: 1.8 | T3: 1.8 | U3: 1.8 | V3: 1.8 | W3: 1.8 | X3: 1.8 | Y3: 1.8 | Z3: 1.8
A4: 3 | B4: 5 | C4: =eh_flow_gas!B2/10.45 -> 2.0995215 | D4: =eh_flow_gas!C2/10.45 -> 1.9404785 | E4: =eh_flow_gas!D2/10.45 -> 2.2919617 | F4: =eh_flow_gas!E2/10.45 -> 2.0732057 | G4: =eh_flow_gas!F2/10.45 -> 2.0385646 | H4: =eh_flow_gas!G2/10.45 -> 1.882201 | I4: =eh_flow_gas!H2/10.45 -> 1.6774163 | J4: =eh_flow_gas!I2/10.45 -> 1.5601914 | ... Z4: =eh_flow_gas!Y2/10.45 -> 2.0456459
A5: 4 | B5: 6 | C5: 0.82008 | D5: 0.82008 | E5: 0.82008 | F5: 0.82008 | G5: 0.82008 | H5: 0.82008 | I5: 0.82008 | J5: 0.82008 | K5: 0.82008 | L5: 0.82008 | M5: 0.82008 | N5: 0.82008 | O5: 0.82008 | P5: 0.82008 | Q5: 0.82008 | R5: 0.82008 | S5: 0.82008 | T5: 0.82008 | U5: 0.82008 | V5: 0.82008 | W5: 0.82008 | X5: 0.82008 | Y5: 0.82008 | Z5: 0.82008

Sheet eh_PCI_gas
A1: type | B1: PCI_ref
A2: gas | B2: 0.2

Sheet heat_Q_demand
A1: load_id | B1: H00 | C1: H01 | D1: H02 | E1: H03 | F1: H04 | G1: H05 | H1: H06 | I1: H07 | J1: H08 | K1: H09 | L1: H10 | M1: H11 | N1: H12 | O1: H13 | P1: H14 | Q1: H15 | R1: H16 | S1: H17 | T1: H18 | U1: H19 | V1: H20 | W1: H21 | X1: H22 | Y1: H23
A2: 1 | B2: 5.943 | C2: 6.17 | D2: 5.936 | E2: 5.364 | F2: 5.636 | G2: 5.698 | H2: 4.915 | I2: 4.601 | J2: 4.395 | K2: 4.062 | L2: 3.47 | M2: 3.578 | N2: 3.268 | O2: 3.143 | P2: 3.36 | Q2: 3.428 | R2: 3.905 | S2: 4.449 | T2: 5.241 | U2: 6.016 | V2: 5.388 | W2: 6.384 | X2: 6.109 | Y2: 6.881
A3: 2 | B3: 6.697 | C3: 5.955 | D3: 6.878 | E3: 6.011 | F3: 5.687 | G3: 5.103 | H3: 4.804 | I3: 4.664 | J3: 4.078 | K3: 3.837 | L3: 3.56 | M3: 3.572 | N3: 3.183 | O3: 3.016 | P3: 3.708 | Q3: 3.688 | R3: 4.401 | S3: 4.652 | T3: 4.961 | U3: 5.567 | V3: 6.563 | W3: 7.015 | X3: 6.543 | Y3: 6.755
A4: 3 | B4: 7.186 | C4: 6.351 | D4: 6.646 | E4: 6.228 | F4: 5.986 | G4: 5.18 | H4: 4.523 | I4: 3.982 | J4: 3.848 | K4: 3.659 | L4: 3.423 | M4: 3.694 | N4: 3.466 | O4: 3.119 | P4: 3.557 | Q4: 3.671 | R4: 4.055 | S4: 4.598 | T4: 5.186 | U4: 5.342 | V4: 6.25 | W4: 5.81 | X4: 6.518 | Y4: 7.733

Sheet ambient_T
A1: env_id | B1: H00 | C1: H01 | D1: H02 | E1: H03 | F1: H04 | G1: H05 | H1: H06 | I1: H07 | J1: H08 | K1: H09 | L1: H10 | M1: H11 | N1: H12 | O1: H13 | P1: H14 | Q1: H15 | R1: H16 | S1: H17 | T1: H18 | U1: H19 | V1: H20 | W1: H21 | X1: H22 | Y1: H23
A2: site_1 | B2: 24.04 | C2: 23.07 | D2: 20.85 | E2: 19.23 | F2: 17.17 | G2: 15.43 | H2: 13.74 | I2: 13.11 | J2: 11.9 | K2: 12.27 | L2: 12.67 | M2: 13.08 | N2: 13.94 | O2: 15.68 | P2: 17.06 | Q2: 19.37 | R2: 20.08 | S2: 22.37 | T2: 23.15 | U2: 24.46 | V2: 26.31 | W2: 26.36 | X2: 25.47 | Y2: 24.46

Sheet storage_dispatch_ch
A1: id | B1: H00 | C1: H01 | D1: H02 | E1: H03 | F1: H04 | G1: H05 | H1: H06 | I1: H07 | J1: H08 | K1: H09 | L1: H10 | M1: H11 | N1: H12 | O1: H13 | P1: H14 | Q1: H15 | R1: H16 | S1: H17 | T1: H18 | U1: H19 | V1: H20 | W1: H21 | X1: H22 | Y1: H23
A2: ES1 | B2: 3 | C2: 3 | D2: 3 | E2: 3 | F2: 3 | G2: 3 | H2: 0 | I2: 0 | J2: 0 | K2: 0 | L2: 0 | M2: 0 | N2: 0 | O2: 0 | P2: 0 | Q2: 0 | R2: 0 | S2: 0 | T2: 0 | U2: 0 | V2: 0 | W2: 0 | X2: 0 | Y2: 0

Sheet storage_dispatch_dc
A1: id | B1: H00 | C1: H01 | D1: H02 | E1: H03 | F1: H04 | G1: H05 | H1: H06 | I1: H07 | J1: H08 | K1: H09 | L1: H10 | M1: H11 | N1: H12 | O1: H13 | P1: H14 | Q1: H15 | R1: H16 | S1: H17 | T1: H18 | U1: H19 | V1: H20 | W1: H21 | X1: H22 | Y1: H23
A2: ES1 | B2: 0 | C2: 0 | D2: 0 | E2: 0 | F2: 0 | G2: 0 | H2: 0 | I2: 0 | J2: 0 | K2: 0 | L2: 0 | M2: 0 | N2: 0 | O2: 0 | P2: 0 | Q2: 0 | R2: 0 | S2: 0 | T2: 4 | U2: 4 | V2: 4 | W2: 4 | X2: 4 | Y2: 4

Sheet elec_price_buy
A1: tariff_id | B1: H00 | C1: H01 | D1: H02 | E1: H03 | F1: H04 | G1: H05 | H1: H06 | I1: H07 | J1: H08 | K1: H09 | L1: H10 | M1: H11 | N1: H12 | O1: H13 | P1: H14 | Q1: H15 | R1: H16 | S1: H17 | T1: H18 | U1: H19 | V1: H20 | W1: H21 | X1: H22 | Y1: H23
A2: default | B2: 0.3 | C2: 0.3 | D2: 0.3 | E2: 0.3 | F2: 0.3 | G2: 0.3 | H2: 0.3 | I2: 0.3 | J2: 0.6 | K2: 0.6 | L2: 0.6 | M2: 0.6 | N2: 0.6 | O2: 0.6 | P2: 0.6 | Q2: 0.6 | R2: 0.6 | S2: 0.6 | T2: 0.6 | U2: 0.6 | V2: 0.6 | W2: 0.3 | X2: 0.3 | Y2: 0.3

Sheet elec_price_sell
A1: tariff_id | B1: H00 | C1: H01 | D1: H02 | E1: H03 | F1: H04 | G1: H05 | H1: H06 | I1: H07 | J1: H08 | K1: H09 | L1: H10 | M1: H11 | N1: H12 | O1: H13 | P1: H14 | Q1: H15 | R1: H16 | S1: H17 | T1: H18 | U1: H19 | V1: H20 | W1: H21 | X1: H22 | Y1: H23
A2: default | B2: 0.2 | C2: 0.2 | D2: 0.2 | E2: 0.2 | F2: 0.2 | G2: 0.2 | H2: 0.2 | I2: 0.2 | J2: 0.4 | K2: 0.4 | L2: 0.4 | M2: 0.4 | N2: 0.4 | O2: 0.4 | P2: 0.4 | Q2: 0.4 | R2: 0.4 | S2: 0.4 | T2: 0.4 | U2: 0.4 | V2: 0.4 | W2: 0.2 | X2: 0.2 | Y2: 0.2

Sheet external_CI
A1: profile_id | B1: H00 | C1: H01 | D1: H02 | E1: H03 | F1: H04 | G1: H05 | H1: H06 | I1: H07 | J1: H08 | K1: H09 | L1: H10 | M1: H11 | N1: H12 | O1: H13 | P1: H14 | Q1: H15 | R1: H16 | S1: H17 | T1: H18 | U1: H19 | V1: H20 | W1: H21 | X1: H22 | Y1: H23
A2: ext_grid | B2: 0.45 | C2: 0.45 | D2: 0.45 | E2: 0.45 | F2: 0.45 | G2: 0.45 | H2: 0.45 | I2: 0.45 | J2: 0.45 | K2: 0.45 | L2: 0.45 | M2: 0.45 | N2: 0.45 | O2: 0.45 | P2: 0.45 | Q2: 0.45 | R2: 0.45 | S2: 0.45 | T2: 0.45 | U2: 0.45 | V2: 0.45 | W2: 0.45 | X2: 0.45 | Y2: 0.45

Sheet grid_trade_buy
A1: profile_id | B1: H00 | C1: H01 | D1: H02 | E1: H03 | F1: H04 | G1: H05 | H1: H06 | I1: H07 | J1: H08 | K1: H09 | L1: H10 | M1: H11 | N1: H12 | O1: H13 | P1: H14 | Q1: H15 | R1: H16 | S1: H17 | T1: H18 | U1: H19 | V1: H20 | W1: H21 | X1: H22 | Y1: H23
A2: ext_grid | B2: 0 | C2: 0 | D2: 0 | E2: 0 | F2: 0 | G2: 0 | H2: 0 | I2: 0 | J2: 0 | K2: 0 | L2: 0 | M2: 0 | N2: 0 | O2: 0 | P2: 0 | Q2: 0 | R2: 0 | S2: 0 | T2: 0 | U2: 0 | V2: 0 | W2: 0 | X2: 0 | Y2: 0

Sheet grid_trade_sell
A1: profile_id | B1: H00 | C1: H01 | D1: H02 | E1: H03 | F1: H04 | G1: H05 | H1: H06 | I1: H07 | J1: H08 | K1: H09 | L1: H10 | M1: H11 | N1: H12 | O1: H13 | P1: H14 | Q1: H15 | R1: H16 | S1: H17 | T1: H18 | U1: H19 | V1: H20 | W1: H21 | X1: H22 | Y1: H23
A2: ext_grid | B2: 0 | C2: 0 | D2: 0 | E2: 0 | F2: 0 | G2: 0 | H2: 0 | I2: 0 | J2: 0 | K2: 0 | L2: 0 | M2: 0 | N2: 0 | O2: 0 | P2: 0 | Q2: 0 | R2: 0 | S2: 0 | T2: 0 | U2: 0 | V2: 0 | W2: 0 | X2: 0 | Y2: 0

Sheet gas_source_output_fixed
A1: source_id | B1: node | C1: H00 | D1: H01 | E1: H02 | F1: H03 | G1: H04 | H1: H05 | I1: H06 | J1: H07 | K1: H08 | L1: H09 | M1: H10 | N1: H11 | O1: H12 | P1: H13 | Q1: H14 | R1: H15 | S1: H16 | T1: H17 | U1: H18 | V1: H19 | W1: H20 | X1: H21 | Y1: H22 | Z1: H23
A2: 1 | B2: 1
A3: 2 | B3: 4 | C3: 2.46 | D3: 2.46 | E3: 2.46 | F3: 2.46 | G3: 2.46 | H3: 2.46 | I3: 2.46 | J3: 2.46 | K3: 2.46 | L3: 2.46 | M3: 2.46 | N3: 2.46 | O3: 2.46 | P3: 2.46 | Q3: 2.46 | R3: 2.46 | S3: 2.46 | T3: 2.46 | U3: 2.46 | V3: 2.46 | W3: 2.46 | X3: 2.46 | Y3: 2.46 | Z3: 2.46
